/home/smazurchuk/.bashrc: line 14: Export: command not found

1. SSH tunnel from your workstation using the following command:
  
   ssh -L 8826:kepler04:8826 smazurchuk@tesla.rcc.mcw.edu
  
   and point your web browser to http://localhost:8826.

2. Copy/paste the token below when you connect for the first time.

[33mWARNING: Skipping user bind, non existent bind point (file) in container: '/usr/bin/nvidia-debugdump'
[0m[33mWARNING: Skipping user bind, non existent bind point (file) in container: '/usr/bin/nvidia-persistenced'
[0m[33mWARNING: Skipping user bind, non existent bind point (file) in container: '/usr/bin/nvidia-cuda-mps-control'
[0m[33mWARNING: Skipping user bind, non existent bind point (file) in container: '/usr/bin/nvidia-cuda-mps-server'
[0m[I 18:15:03.424 NotebookApp] JupyterLab extension loaded from /usr/local/lib/python3.5/dist-packages/jupyterlab
[I 18:15:03.424 NotebookApp] JupyterLab application directory is /usr/local/share/jupyter/lab
[I 18:15:03.426 NotebookApp] Serving notebooks from local directory: /home/smazurchuk/BM/code
[I 18:15:03.426 NotebookApp] The Jupyter Notebook is running at:
[I 18:15:03.426 NotebookApp] http://kepler04:8826/?token=cebd7eb5684abfffa9d5005d0b9bcb8d7461b0a07933979f
[I 18:15:03.426 NotebookApp] Use Control-C to stop this server and shut down all kernels (twice to skip confirmation).
[C 18:15:03.440 NotebookApp] 
    
    To access the notebook, open this file in a browser:
        file:///home/smazurchuk/.local/share/jupyter/runtime/nbserver-31483-open.html
    Or copy and paste one of these URLs:
        http://kepler04:8826/?token=cebd7eb5684abfffa9d5005d0b9bcb8d7461b0a07933979f
[I 18:15:36.360 NotebookApp] 302 GET / (141.106.226.90) 1.02ms
[I 18:15:36.383 NotebookApp] 302 GET /tree? (141.106.226.90) 1.00ms
[W 18:15:44.688 NotebookApp] Not allowing login redirect to '/tree?'
[I 18:15:44.690 NotebookApp] 302 POST /login?next=%2Ftree%3F (141.106.226.90) 4.24ms
[I 18:15:44.705 NotebookApp] 302 GET / (141.106.226.90) 0.57ms
[I 18:16:02.340 NotebookApp] Creating new notebook in 
/usr/local/lib/python3.5/dist-packages/jupyter_client/connect.py:163: RuntimeWarning: Failed to set sticky bit on '/home/smazurchuk/.local/share/jupyter/runtime/kernel-6530b6ac-606c-423a-afa0-a33ed5c3fffa.json': [Errno 22] Invalid argument: '/home/smazurchuk/.local/share/jupyter/runtime/kernel-6530b6ac-606c-423a-afa0-a33ed5c3fffa.json'
Probably not a big deal, but runtime files may be cleaned up periodically.
  RuntimeWarning,
[E 18:16:03.417 NotebookApp] Failed to run command:
    ['/rcc/shared/apps/python/3.6.4/bin/python3.6', '-m', 'ipykernel_launcher', '-f', '/home/smazurchuk/.local/share/jupyter/runtime/kernel-6530b6ac-606c-423a-afa0-a33ed5c3fffa.json']
        PATH='/usr/local/bin:/cuda/bin:/nvidia:/usr/local/sbin:/usr/local/bin:/usr/sbin:/usr/bin:/sbin:/bin'
        with kwargs:
    {'stderr': None, 'cwd': '/home/smazurchuk/BM/code', 'start_new_session': True, 'stdout': None, 'stdin': -1}
    
[E 18:16:03.418 NotebookApp] Uncaught exception POST /api/sessions (141.106.226.90)
    HTTPServerRequest(protocol='http', host='localhost:8826', method='POST', uri='/api/sessions', version='HTTP/1.1', remote_ip='141.106.226.90')
    Traceback (most recent call last):
      File "/usr/local/lib/python3.5/dist-packages/tornado/web.py", line 1699, in _execute
        result = await result
      File "/usr/lib/python3.5/asyncio/futures.py", line 363, in __iter__
        return self.result()  # May raise too.
      File "/usr/lib/python3.5/asyncio/futures.py", line 274, in result
        raise self._exception
      File "/usr/local/lib/python3.5/dist-packages/tornado/gen.py", line 736, in run
        yielded = self.gen.throw(*exc_info)  # type: ignore
      File "/usr/local/lib/python3.5/dist-packages/notebook/services/sessions/handlers.py", line 73, in post
        type=mtype))
      File "/usr/local/lib/python3.5/dist-packages/tornado/gen.py", line 729, in run
        value = future.result()
      File "/usr/lib/python3.5/asyncio/futures.py", line 274, in result
        raise self._exception
      File "/usr/local/lib/python3.5/dist-packages/tornado/gen.py", line 736, in run
        yielded = self.gen.throw(*exc_info)  # type: ignore
      File "/usr/local/lib/python3.5/dist-packages/notebook/services/sessions/sessionmanager.py", line 79, in create_session
        kernel_id = yield self.start_kernel_for_session(session_id, path, name, type, kernel_name)
      File "/usr/local/lib/python3.5/dist-packages/tornado/gen.py", line 729, in run
        value = future.result()
      File "/usr/lib/python3.5/asyncio/futures.py", line 274, in result
        raise self._exception
      File "/usr/local/lib/python3.5/dist-packages/tornado/gen.py", line 736, in run
        yielded = self.gen.throw(*exc_info)  # type: ignore
      File "/usr/local/lib/python3.5/dist-packages/notebook/services/sessions/sessionmanager.py", line 92, in start_kernel_for_session
        self.kernel_manager.start_kernel(path=kernel_path, kernel_name=kernel_name)
      File "/usr/local/lib/python3.5/dist-packages/tornado/gen.py", line 729, in run
        value = future.result()
      File "/usr/lib/python3.5/asyncio/futures.py", line 274, in result
        raise self._exception
      File "/usr/local/lib/python3.5/dist-packages/tornado/gen.py", line 209, in wrapper
        yielded = next(result)
      File "/usr/local/lib/python3.5/dist-packages/notebook/services/kernels/kernelmanager.py", line 160, in start_kernel
        super(MappingKernelManager, self).start_kernel(**kwargs)
      File "/usr/local/lib/python3.5/dist-packages/jupyter_client/multikernelmanager.py", line 110, in start_kernel
        km.start_kernel(**kwargs)
      File "/usr/local/lib/python3.5/dist-packages/jupyter_client/manager.py", line 259, in start_kernel
        **kw)
      File "/usr/local/lib/python3.5/dist-packages/jupyter_client/manager.py", line 204, in _launch_kernel
        return launch_kernel(kernel_cmd, **kw)
      File "/usr/local/lib/python3.5/dist-packages/jupyter_client/launcher.py", line 138, in launch_kernel
        proc = Popen(cmd, **kwargs)
      File "/usr/lib/python3.5/subprocess.py", line 947, in __init__
        restore_signals, start_new_session)
      File "/usr/lib/python3.5/subprocess.py", line 1551, in _execute_child
        raise child_exception_type(errno_num, err_msg)
    FileNotFoundError: [Errno 2] No such file or directory: '/rcc/shared/apps/python/3.6.4/bin/python3.6'
[W 18:16:03.427 NotebookApp] Unhandled error
[E 18:16:03.428 NotebookApp] {
      "Content-Length": "99",
      "Host": "localhost:8826",
      "Connection": "keep-alive",
      "Content-Type": "application/json",
      "Accept": "application/json, text/javascript, */*; q=0.01",
      "Accept-Language": "en-US,en;q=0.5",
      "X-Requested-With": "XMLHttpRequest",
      "Accept-Encoding": "gzip, deflate",
      "X-Xsrftoken": "2|31f17884|72aeb8f2611ef243e453b696f5ff84bf|1561476206",
      "User-Agent": "Mozilla/5.0 (X11; Ubuntu; Linux x86_64; rv:67.0) Gecko/20100101 Firefox/67.0",
      "Referer": "http://localhost:8826/notebooks/Untitled2.ipynb?kernel_name=topicembedding",
      "Cookie": "_xsrf=2|31f17884|72aeb8f2611ef243e453b696f5ff84bf|1561476206; username-localhost-8899=\"2|1:0|10:1561480127|23:username-localhost-8899|44:NmJmN2QxZDMxZWI2NDI4NTg2ZmIxMDE1MTgyZTI3MDA=|db4757cc0ce43e94ae3d5153203e94c6378cb8d529c6e25e8f65b75cba3676b6\"; username-localhost-9875=\"2|1:0|10:1561486044|23:username-localhost-9875|44:NDk2OWJhNjZjODVhNDY1MDk5NTI0Y2E0YmExZDEwN2Q=|2d99b56dbbaf033ffe75d6401805ec2f78ef4ebe932da57ade0fdecf1600980c\"; username-localhost-8826=\"2|1:0|10:1561486544|23:username-localhost-8826|44:YmNiNjU5ZjVkYzliNDYyMjg4YmM1MzRhNzllZDYzNzY=|a4b0704a9aff2ddb8c4a6dad49a7e2cf88e06d6688901fcbae5a68f236e6c774\""
    }
[E 18:16:03.428 NotebookApp] 500 POST /api/sessions (141.106.226.90) 52.24ms referer=http://localhost:8826/notebooks/Untitled2.ipynb?kernel_name=topicembedding
[I 18:16:18.173 NotebookApp] Saving file at /Untitled2.ipynb
[I 18:16:19.344 NotebookApp] Shutting down on /api/shutdown request.
[I 18:16:19.349 NotebookApp] Shutting down 0 kernels
